Traceback (most recent call last):
  File "/Users/kootsoop/opt/anaconda3/lib/python3.9/site-packages/jupyter_cache/executors/utils.py", line 51, in single_nb_execution
    executenb(
  File "/Users/kootsoop/opt/anaconda3/lib/python3.9/site-packages/nbclient/client.py", line 1204, in execute
    return NotebookClient(nb=nb, resources=resources, km=km, **kwargs).execute()
  File "/Users/kootsoop/opt/anaconda3/lib/python3.9/site-packages/nbclient/util.py", line 84, in wrapped
    return just_run(coro(*args, **kwargs))
  File "/Users/kootsoop/opt/anaconda3/lib/python3.9/site-packages/nbclient/util.py", line 62, in just_run
    return loop.run_until_complete(coro)
  File "/Users/kootsoop/opt/anaconda3/lib/python3.9/asyncio/base_events.py", line 647, in run_until_complete
    return future.result()
  File "/Users/kootsoop/opt/anaconda3/lib/python3.9/site-packages/nbclient/client.py", line 663, in async_execute
    await self.async_execute_cell(
  File "/Users/kootsoop/opt/anaconda3/lib/python3.9/site-packages/nbclient/client.py", line 965, in async_execute_cell
    await self._check_raise_for_error(cell, cell_index, exec_reply)
  File "/Users/kootsoop/opt/anaconda3/lib/python3.9/site-packages/nbclient/client.py", line 862, in _check_raise_for_error
    raise CellExecutionError.from_cell_and_msg(cell, exec_reply_content)
nbclient.exceptions.CellExecutionError: An error occurred while executing the following cell:
------------------
import schemdraw
import schemdraw.elements as elm
with schemdraw.Drawing(file='sloppy-3.svg') as d:
    d += elm.SourceI().label('$4~mA$').up()
    d += elm.Line().right()
    d.push()
    d += (R1 := elm.Resistor().down())
    d += elm.CurrentLabelInline(direction='in', ofst=0.3).at(R2.end).label('$I_x$')
    d.pop()
    d += elm.Line().right()
    d += elm.SourceControlledI().down().label('$3I_x$')
    d += elm.Line().left().length(6)
------------------

[0;31m---------------------------------------------------------------------------[0m
[0;31mNameError[0m                                 Traceback (most recent call last)
[0;32m/var/folders/65/qy_bbqpj2x3470cgr0fmhyc40000gn/T/ipykernel_8587/1787042461.py[0m in [0;36m<module>[0;34m[0m
[1;32m      6[0m     [0md[0m[0;34m.[0m[0mpush[0m[0;34m([0m[0;34m)[0m[0;34m[0m[0;34m[0m[0m
[1;32m      7[0m     [0md[0m [0;34m+=[0m [0;34m([0m[0mR1[0m [0;34m:=[0m [0melm[0m[0;34m.[0m[0mResistor[0m[0;34m([0m[0;34m)[0m[0;34m.[0m[0mdown[0m[0;34m([0m[0;34m)[0m[0;34m)[0m[0;34m[0m[0;34m[0m[0m
[0;32m----> 8[0;31m     [0md[0m [0;34m+=[0m [0melm[0m[0;34m.[0m[0mCurrentLabelInline[0m[0;34m([0m[0mdirection[0m[0;34m=[0m[0;34m'in'[0m[0;34m,[0m [0mofst[0m[0;34m=[0m[0;36m0.3[0m[0;34m)[0m[0;34m.[0m[0mat[0m[0;34m([0m[0mR2[0m[0;34m.[0m[0mend[0m[0;34m)[0m[0;34m.[0m[0mlabel[0m[0;34m([0m[0;34m'$I_x$'[0m[0;34m)[0m[0;34m[0m[0;34m[0m[0m
[0m[1;32m      9[0m     [0md[0m[0;34m.[0m[0mpop[0m[0;34m([0m[0;34m)[0m[0;34m[0m[0;34m[0m[0m
[1;32m     10[0m     [0md[0m [0;34m+=[0m [0melm[0m[0;34m.[0m[0mLine[0m[0;34m([0m[0;34m)[0m[0;34m.[0m[0mright[0m[0;34m([0m[0;34m)[0m[0;34m[0m[0;34m[0m[0m

[0;31mNameError[0m: name 'R2' is not defined
NameError: name 'R2' is not defined

