Traceback (most recent call last):
  File "/Users/kootsoop/opt/anaconda3/lib/python3.9/site-packages/jupyter_cache/executors/utils.py", line 51, in single_nb_execution
    executenb(
  File "/Users/kootsoop/opt/anaconda3/lib/python3.9/site-packages/nbclient/client.py", line 1204, in execute
    return NotebookClient(nb=nb, resources=resources, km=km, **kwargs).execute()
  File "/Users/kootsoop/opt/anaconda3/lib/python3.9/site-packages/nbclient/util.py", line 84, in wrapped
    return just_run(coro(*args, **kwargs))
  File "/Users/kootsoop/opt/anaconda3/lib/python3.9/site-packages/nbclient/util.py", line 62, in just_run
    return loop.run_until_complete(coro)
  File "/Users/kootsoop/opt/anaconda3/lib/python3.9/asyncio/base_events.py", line 647, in run_until_complete
    return future.result()
  File "/Users/kootsoop/opt/anaconda3/lib/python3.9/site-packages/nbclient/client.py", line 663, in async_execute
    await self.async_execute_cell(
  File "/Users/kootsoop/opt/anaconda3/lib/python3.9/site-packages/nbclient/client.py", line 965, in async_execute_cell
    await self._check_raise_for_error(cell, cell_index, exec_reply)
  File "/Users/kootsoop/opt/anaconda3/lib/python3.9/site-packages/nbclient/client.py", line 862, in _check_raise_for_error
    raise CellExecutionError.from_cell_and_msg(cell, exec_reply_content)
nbclient.exceptions.CellExecutionError: An error occurred while executing the following cell:
------------------
import schemdraw
import schemdraw.elements as elm
with schemdraw.Drawing(file='parallel-current-1.svg') as d:
   d += elm.SourceI().up().label('$I_1$\n3A')
   d += elm.Line().right().length(6)
   d += (R1 := elm.Resistor().label('$R$\n$10\Omega$').down())
   d += elm.CurrentLabelInline(direction='in').at(R1).label('$I_R$')
   d += elm.Line().left()
   d.push()
   d += elm.SourceI().up().label('$I_2$\n2A')
   p.pop()
   d += elm.Line().left()
------------------

[0;31m---------------------------------------------------------------------------[0m
[0;31mNameError[0m                                 Traceback (most recent call last)
[0;32m/var/folders/65/qy_bbqpj2x3470cgr0fmhyc40000gn/T/ipykernel_6907/2914727505.py[0m in [0;36m<module>[0;34m[0m
[1;32m      9[0m    [0md[0m[0;34m.[0m[0mpush[0m[0;34m([0m[0;34m)[0m[0;34m[0m[0;34m[0m[0m
[1;32m     10[0m    [0md[0m [0;34m+=[0m [0melm[0m[0;34m.[0m[0mSourceI[0m[0;34m([0m[0;34m)[0m[0;34m.[0m[0mup[0m[0;34m([0m[0;34m)[0m[0;34m.[0m[0mlabel[0m[0;34m([0m[0;34m'$I_2$\n2A'[0m[0;34m)[0m[0;34m[0m[0;34m[0m[0m
[0;32m---> 11[0;31m    [0mp[0m[0;34m.[0m[0mpop[0m[0;34m([0m[0;34m)[0m[0;34m[0m[0;34m[0m[0m
[0m[1;32m     12[0m    [0md[0m [0;34m+=[0m [0melm[0m[0;34m.[0m[0mLine[0m[0;34m([0m[0;34m)[0m[0;34m.[0m[0mleft[0m[0;34m([0m[0;34m)[0m[0;34m[0m[0;34m[0m[0m

[0;31mNameError[0m: name 'p' is not defined
NameError: name 'p' is not defined

